Workbook

Sheet ホワイトペーパー_テスト項目
A1: ** ホワイトペーパーの生成フロー
A3: A.WP1 | B3: white-paper-transcription-creation
B4: 条件・処理の流れ | H4: 確認内容
B5: 1 | C5: wavファイル受信：0 バイトのファイル | H5: DBが更新されるか？エラーはあるか?
C6: Azure経由で処理する
B7: 2 | C7: wavファイル受信：テキストを生成する音声なしのファイル | H7: DBが更新されるか？エラーはあるか?
C8: Azure経由で処理する
B9: 3 | C9: wavファイル受信：録音ファイル | H9: DBが更新されるか？エラーはあるか?
C10: Azure経由で処理する
B11: 4 | C11: wavファイル受信：テキストを生成する音声ありのファイル、30分のファイル | H11: DBが更新されるか？エラーはあるか?
C12: 関数の処理時間が 30 分以内で成功する
B13: 5 | C13: wavファイル受信：テキストを生成する音声ありのファイル、30分のファイル | H13: DBが更新されるか？エラーはあるか?
C14: 関数の処理時間が 30分以上で、例外タイムアウトがスローされる
B15: 6 | C15: wavファイル受信：テキストを生成する音声ありのファイル、30分のファイル | H15: DBが更新されるか？エラーはあるか?
C16: エラーが発生し (タイムアウト エラーではない)、例外がスローされる
B17: 7 | C17: wavファイル受信：テキストを生成する音声ありのファイル、30分のファイル | H17: DBが更新されるか？エラーはあるか?
C18: エラーが発生し (タイムアウト エラーではない)、例外がスローされない
B19: 8 | C19: wavファイル受信：テキストを生成する音声ありのファイル、2時間のファイル | F19: _ | H19: DBが更新されるか？エラーはあるか?
C20: 関数の処理時間が 30 分以内で成功する
B21: 9 | C21: wavファイル受信：テキストを生成する音声ありのファイル、2時間のファイル | H21: DBが更新されるか？エラーはあるか?
C22: 関数の処理時間が 30分以上で、例外タイムアウトがスローされる
B23: 10 | C23: wavファイル受信：テキストを生成する音声ありのファイル、2時間のファイル | H23: DBが更新されるか？エラーはあるか?
C24: エラーが発生し (タイムアウト エラーではない)、例外がスローされる
B25: 11 | C25: wavファイル受信：テキストを生成する音声ありのファイル、2時間のファイル | H25: DBが更新されるか？エラーはあるか?
C26: エラーが発生し (タイムアウト エラーではない)、例外がスローされない
B27: 12 | C27: 生のテキストをコレクションに取得する | H27: DBが更新されるか？
B30: 条件 | D30: ステップ・処理の流れ | H30: 観点ID： | I30: 45748 | J30: 追加/生成に成功した場合 | L30: 観点ID： | M30: 45749 | N30: 追加/生成に失敗した場合 | P30: 観点ID： | Q30: 45690 | R30: DBの内容は正しく更新されているか？ | X30: データがcollection [usage_stat]に挿入される | AA30: データがcollection [transcript]に挿入される
H31: パターンID | J31: 結果 | L31: パターンID | N31: 結果 | P31: パターンID | R31: 結果 | X31: id | Y31: Usage statistics ID | AA31: id | AB31: IN_PROGRESS_TRANSCRIPT
B32: 1 | D32: 1. wavファイルの受信：0 バイトのファイル | L32: 45749 | M32: WP1_A_1 | N32: ファイルの生成に失敗し、以下のメッセージが表示されること | X32: ai_model_id | Y32: Used AI model ID | AA32: target_id | AB32: target.target_id
D33: 2. Azure経由で処理する | N33: ファイル選択必須。0Byte以上のファイルを選択してください。 | X33: input_token | Y33: Number of input tokens | AA33: text | AB33: from Azure
X34: output_token | Y34: Number of output tokens | AA34: progress | AB34: RAW_DATA
B35: 2 | D35: 1. wavファイルの受信：テキストを生成する音声なしのファイル | L35: 45749 | M35: WP1_A_2 | N35: ファイルの生成に失敗すること | X35: created_by | Y35: Summary creator and editor user ID | AA35: created_at | AB35: time()
D36: 2. Azure経由で処理する | X36: year | Y36: Statistics year | AA36: updated_at | AB36: time()
X37: month | Y37: Statistics month | AA37: deleted_at | AB37: null
B38: 3 | D38: 1. wav ファイルの受信: テキストを生成する音声ありのファイル、 30分のファイル | H38: 45748 | I38: WP1_A_3 | J38: 生成に成功すること | P38: 45690 | Q38: WP1_A_3_1 | R38: データがcollecion [target] に更新されること status:IN_PROGRESS_TRANSCRIPT | X38: collection_name | Y38: Collection name | AA38: collection_name | AB38: Name of Meeting
D39: 2. 関数の処理時間が30分以内で成功する | P39: 45690 | Q39: WP1_A_3_2 | R39: データがcollection[usage_stat]に更新されること | X39: データがcollection [log]に挿入される | AA39: データがpoison queue[target]に挿入される
X40: id | Y40: Key(id) | AA40: status | AB40: ERROR
B41: 4 | D41: 1. wav ファイルの受信: テキストを生成する音声ありのファイル、 30分のファイル | L41: 45749 | M41: WP1_A_4 | N41: ファイルの生成に失敗すること | P41: 45690 | Q41: WP1_A_4 | R41: データがpoison queue[target]に更新されること | X41: target_id | Y41: 対象ID | AA41: error_detail | AB41: エラー詳細
D42: 2. 関数の処理時間が 30分以内で、例外タイムアウトがスローされる | R42: データがcollection [log]に更新されること | X42: type | Y42: 0:OK, 1:ERROR | AA42: updated_by
X43: date | AA43: updated_at
...

Sheet テスト結果
A1: 項番 | B1: 機能 | E1: 観点ID | F1: 評価観点 | G1: 正常 異常 | H1: パターンID | I1: Điều kiện đánh giá | J1: Nội dung xác nhận | K1: 開発評価結果 | N1: ステータス評価結果 | S1: バグ番号 開発環境 | T1: バグ番号 ステージング環境 | U1: 備考
A2: =IF(J2="","",ROW()-2) -> 0 | B2: =IFERROR(VLOOKUP($E2,Viewpoint!$A:$D,2,FALSE)&"","") | C2: =IFERROR(VLOOKUP($E2,Viewpoint!$A:$D,3,FALSE)&"","") | D2: =IFERROR(VLOOKUP($E2,Viewpoint_bk!$A:$D,4,FALSE)&"","") | E2: 1-1 | F2: =IFERROR(VLOOKUP($E2,Viewpoint!$A:$E,5,FALSE)&"","") | G2: Nomal | H2: CM_D_1 | I2: Tham chiếu sheet "Testcase_common" | J2: Tham chiếu sheet "Testcase_common" | K2: OK | L2: 15-04-2025 | M2: DaiHM | P2: ThuyNTP
A3: =IF(J3="","",ROW()-2) -> 1 | B3: =IFERROR(VLOOKUP($E3,Viewpoint!$A:$D,2,FALSE)&"","") | C3: =IFERROR(VLOOKUP($E3,Viewpoint!$A:$D,3,FALSE)&"","") | D3: =IFERROR(VLOOKUP($E3,Viewpoint_bk!$A:$D,4,FALSE)&"","") | E3: 1-1 | F3: =IF(E3="","",IF(E3=E2,"同上",IFERROR(VLOOKUP($E3,Viewpoint!$A:$E,5,FALSE)&"",""))) -> 同上 | G3: Nomal | H3: CM_D_2 | I3: 同上 | J3: 同上 | K3: OK | L3: 15-04-2025 | M3: DaiHM
A4: =IF(J4="","",ROW()-2) -> 2 | B4: =IFERROR(VLOOKUP($E4,Viewpoint!$A:$D,2,FALSE)&"","") | C4: =IFERROR(VLOOKUP($E4,Viewpoint!$A:$D,3,FALSE)&"","") | D4: =IFERROR(VLOOKUP($E4,Viewpoint_bk!$A:$D,4,FALSE)&"","") | E4: 2-1 | F4: =IFERROR(VLOOKUP($E4,Viewpoint!$A:$E,5,FALSE)&"","") | G4: Nomal | H4: CM_A_1 | I4: 同上 | J4: 同上 | K4: OK | L4: 15-04-2025 | M4: DaiHM
A5: =IF(J5="","",ROW()-2) -> 3 | B5: =IFERROR(VLOOKUP($E5,Viewpoint!$A:$D,2,FALSE)&"","") | C5: =IFERROR(VLOOKUP($E5,Viewpoint!$A:$D,3,FALSE)&"","") | D5: =IFERROR(VLOOKUP($E5,Viewpoint_bk!$A:$D,4,FALSE)&"","") | E5: 2-1 | F5: =IF(E5="","",IF(E5=E4,"同上",IFERROR(VLOOKUP($E5,Viewpoint!$A:$E,5,FALSE)&"",""))) -> 同上 | G5: Nomal | H5: CM_A_2 | I5: 同上 | J5: 同上 | K5: OK | L5: 15-04-2025 | M5: DaiHM
A6: =IF(J6="","",ROW()-2) -> 4 | B6: =IFERROR(VLOOKUP($E6,Viewpoint!$A:$D,2,FALSE)&"","") | C6: =IFERROR(VLOOKUP($E6,Viewpoint!$A:$D,3,FALSE)&"","") | D6: =IFERROR(VLOOKUP($E6,Viewpoint_bk!$A:$D,4,FALSE)&"","") | E6: 2-1 | F6: =IF(E6="","",IF(E6=E5,"同上",IFERROR(VLOOKUP($E6,Viewpoint!$A:$E,5,FALSE)&"",""))) -> 同上 | G6: Nomal | H6: CM_A_3 | I6: 同上 | J6: 同上 | K6: NG | L6: 15-04-2025 | M6: DaiHM
A7: =IF(J7="","",ROW()-2) -> 5 | B7: =IFERROR(VLOOKUP($E7,Viewpoint!$A:$D,2,FALSE)&"","") | C7: =IFERROR(VLOOKUP($E7,Viewpoint!$A:$D,3,FALSE)&"","") | D7: =IFERROR(VLOOKUP($E7,Viewpoint_bk!$A:$D,4,FALSE)&"","") | E7: 1-2 | F7: =IF(E7="","",IF(E7=E6,"同上",IFERROR(VLOOKUP($E7,Viewpoint!$A:$E,5,FALSE)&"",""))) | G7: Nomal | H7: CM_B_1 | I7: 同上 | J7: 同上 | K7: OK | L7: 15-04-2025 | M7: DaiHM
A8: =IF(J8="","",ROW()-2) -> 6 | B8: =IFERROR(VLOOKUP($E8,Viewpoint!$A:$D,2,FALSE)&"","") | C8: =IFERROR(VLOOKUP($E8,Viewpoint!$A:$D,3,FALSE)&"","") | D8: =IFERROR(VLOOKUP($E8,Viewpoint_bk!$A:$D,4,FALSE)&"","") | E8: 1-2 | F8: =IF(E8="","",IF(E8=E7,"同上",IFERROR(VLOOKUP($E8,Viewpoint!$A:$E,5,FALSE)&"",""))) -> 同上 | G8: Nomal | H8: CM_B_2_2 | I8: 同上 | J8: 同上 | K8: OK | L8: 15-04-2025 | M8: DaiHM
A9: =IF(J9="","",ROW()-2) -> 7 | B9: =IFERROR(VLOOKUP($E9,Viewpoint!$A:$D,2,FALSE)&"","") | C9: =IFERROR(VLOOKUP($E9,Viewpoint!$A:$D,3,FALSE)&"","") | D9: =IFERROR(VLOOKUP($E9,Viewpoint_bk!$A:$D,4,FALSE)&"","") | E9: 1-2 | F9: =IF(E9="","",IF(E9=E8,"同上",IFERROR(VLOOKUP($E9,Viewpoint!$A:$E,5,FALSE)&"",""))) -> 同上 | G9: Nomal | H9: CM_B_3_2 | I9: 同上 | J9: 同上 | K9: OK | L9: 15-04-2025 | M9: DaiHM
A10: =IF(J10="","",ROW()-2) -> 8 | B10: =IFERROR(VLOOKUP($E10,Viewpoint!$A:$D,2,FALSE)&"","") | C10: =IFERROR(VLOOKUP($E10,Viewpoint!$A:$D,3,FALSE)&"","") | D10: =IFERROR(VLOOKUP($E10,Viewpoint_bk!$A:$D,4,FALSE)&"","") | E10: 1-2 | F10: =IF(E10="","",IF(E10=E9,"同上",IFERROR(VLOOKUP($E10,Viewpoint!$A:$E,5,FALSE)&"",""))) -> 同上 | G10: Nomal | H10: CM_B_4_2 | I10: 同上 | J10: 同上 | K10: OK | L10: 15-04-2025 | M10: DaiHM
A11: =IF(J11="","",ROW()-2) -> 9 | B11: =IFERROR(VLOOKUP($E11,Viewpoint!$A:$D,2,FALSE)&"","") | C11: =IFERROR(VLOOKUP($E11,Viewpoint!$A:$D,3,FALSE)&"","") | D11: =IFERROR(VLOOKUP($E11,Viewpoint_bk!$A:$D,4,FALSE)&"","") | E11: 1-2 | F11: =IF(E11="","",IF(E11=E10,"同上",IFERROR(VLOOKUP($E11,Viewpoint!$A:$E,5,FALSE)&"",""))) -> 同上 | G11: Nomal | H11: CM_B_5_2 | I11: 同上 | J11: 同上 | K11: OK | L11: 15-04-2025 | M11: DaiHM
A12: =IF(J12="","",ROW()-2) -> 10 | B12: =IFERROR(VLOOKUP($E12,Viewpoint!$A:$D,2,FALSE)&"","") | C12: =IFERROR(VLOOKUP($E12,Viewpoint!$A:$D,3,FALSE)&"","") | D12: =IFERROR(VLOOKUP($E12,Viewpoint_bk!$A:$D,4,FALSE)&"","") | E12: 1-2 | F12: =IF(E12="","",IF(E12=E11,"同上",IFERROR(VLOOKUP($E12,Viewpoint!$A:$E,5,FALSE)&"",""))) -> 同上 | G12: Nomal | H12: CM_B_6_2 | I12: 同上 | J12: 同上 | K12: OK | L12: 15-04-2025 | M12: DaiHM
A13: =IF(J13="","",ROW()-2) -> 11 | B13: =IFERROR(VLOOKUP($E13,Viewpoint!$A:$D,2,FALSE)&"","") | C13: =IFERROR(VLOOKUP($E13,Viewpoint!$A:$D,3,FALSE)&"","") | D13: =IFERROR(VLOOKUP($E13,Viewpoint_bk!$A:$D,4,FALSE)&"","") | E13: 1-2 | F13: =IF(E13="","",IF(E13=E12,"同上",IFERROR(VLOOKUP($E13,Viewpoint!$A:$E,5,FALSE)&"",""))) -> 同上 | G13: Nomal | H13: CM_B_7_2 | I13: 同上 | J13: 同上 | K13: OK | L13: 15-04-2025 | M13: DaiHM
A14: =IF(J14="","",ROW()-2) -> 12 | B14: =IFERROR(VLOOKUP($E14,Viewpoint!$A:$D,2,FALSE)&"","") | C14: =IFERROR(VLOOKUP($E14,Viewpoint!$A:$D,3,FALSE)&"","") | D14: =IFERROR(VLOOKUP($E14,Viewpoint_bk!$A:$D,4,FALSE)&"","") | E14: 1-2 | F14: =IF(E14="","",IF(E14=E13,"同上",IFERROR(VLOOKUP($E14,Viewpoint!$A:$E,5,FALSE)&"",""))) -> 同上 | G14: Nomal | H14: CM_B_8 | I14: 同上 | J14: 同上 | K14: OK | L14: 15-04-2025 | M14: DaiHM
A15: =IF(J15="","",ROW()-2) -> 13 | B15: =IFERROR(VLOOKUP($E15,Viewpoint!$A:$D,2,FALSE)&"","") | C15: =IFERROR(VLOOKUP($E15,Viewpoint!$A:$D,3,FALSE)&"","") | D15: =IFERROR(VLOOKUP($E15,Viewpoint_bk!$A:$D,4,FALSE)&"","") | E15: 1-2 | F15: =IF(E15="","",IF(E15=E14,"同上",IFERROR(VLOOKUP($E15,Viewpoint!$A:$E,5,FALSE)&"",""))) -> 同上 | G15: Nomal | H15: CM_B_9 | I15: 同上 | J15: 同上 | K15: OK | L15: 15-04-2025 | M15: DaiHM
A16: =IF(J16="","",ROW()-2) -> 14 | B16: =IFERROR(VLOOKUP($E16,Viewpoint!$A:$D,2,FALSE)&"","") | C16: =IFERROR(VLOOKUP($E16,Viewpoint!$A:$D,3,FALSE)&"","") | D16: =IFERROR(VLOOKUP($E16,Viewpoint_bk!$A:$D,4,FALSE)&"","") | E16: 4-3 | F16: =IF(E16="","",IF(E16=E15,"同上",IFERROR(VLOOKUP($E16,Viewpoint!$A:$E,5,FALSE)&"",""))) | G16: Nomal | H16: CM_B_10 | I16: 同上 | J16: 同上 | K16: OK | L16: 15-04-2025 | M16: DaiHM
... A26: =IF(J26="","",ROW()-2) -> 24 | B26: =IFERROR(VLOOKUP($E26,Viewpoint!$A:$D,2,FALSE)&"","") | C26: =IFERROR(VLOOKUP($E26,Viewpoint!$A:$D,3,FALSE)&"","") | D26: =IFERROR(VLOOKUP($E26,Viewpoint_bk!$A:$D,4,FALSE)&"","") | E26: 2-1 | F26: =IF(E26="","",IF(E26=E25,"同上",IFERROR(VLOOKUP($E26,Viewpoint!$A:$E,5,FALSE)&"",""))) -> 同上 | G26: Nomal | H26: CM_B_8 | I26: 同上 | J26: 同上 | K26: OK | L26: 15-04-2025 | M26: DaiHM
A27: =IF(J27="","",ROW()-2) -> 25 | B27: =IFERROR(VLOOKUP($E27,Viewpoint!$A:$D,2,FALSE)&"","") | C27: =IFERROR(VLOOKUP($E27,Viewpoint!$A:$D,3,FALSE)&"","") | D27: =IFERROR(VLOOKUP($E27,Viewpoint_bk!$A:$D,4,FALSE)&"","") | E27: 2-1 | F27: =IF(E27="","",IF(E27=E25,"同上",IFERROR(VLOOKUP($E27,Viewpoint!$A:$E,5,FALSE)&"",""))) -> 同上 | G27: Nomal | H27: CM_B_9 | I27: 同上 | J27: 同上 | K27: OK | L27: 15-04-2025 | M27: DaiHM
A28: =IF(J28="","",ROW()-2) -> 26 | B28: =IFERROR(VLOOKUP($E28,Viewpoint!$A:$D,2,FALSE)&"","") | C28: =IFERROR(VLOOKUP($E28,Viewpoint!$A:$D,3,FALSE)&"","") | D28: =IFERROR(VLOOKUP($E28,Viewpoint_bk!$A:$D,4,FALSE)&"","") | E28: 2-1 | F28: =IF(E28="","",IF(E28=E27,"同上",IFERROR(VLOOKUP($E28,Viewpoint!$A:$E,5,FALSE)&"",""))) -> 同上 | G28: Nomal | H28: CM_B_10 | I28: 同上 | J28: 同上 | K28: OK | L28: 15-04-2025 | M28: DaiHM
A29: =IF(J29="","",ROW()-2) -> 27 | B29: =IFERROR(VLOOKUP($E29,Viewpoint!$A:$D,2,FALSE)&"","") | C29: =IFERROR(VLOOKUP($E29,Viewpoint!$A:$D,3,FALSE)&"","") | D29: =IFERROR(VLOOKUP($E29,Viewpoint_bk!$A:$D,4,FALSE)&"","") | E29: 2-1 | F29: =IF(E29="","",IF(E29=E28,"同上",IFERROR(VLOOKUP($E29,Viewpoint!$A:$E,5,FALSE)&"",""))) -> 同上 | G29: Nomal | H29: CM_B_11 | I29: 同上 | J29: 同上 | K29: OK | L29: 15-04-2025 | M29: DaiHM
A30: =IF(J30="","",ROW()-2) -> 28 | B30: =IFERROR(VLOOKUP($E30,Viewpoint!$A:$D,2,FALSE)&"","") | C30: =IFERROR(VLOOKUP($E30,Viewpoint!$A:$D,3,FALSE)&"","") | D30: =IFERROR(VLOOKUP($E30,Viewpoint_bk!$A:$D,4,FALSE)&"","") | E30: 2-1 | F30: =IF(E30="","",IF(E30=E29,"同上",IFERROR(VLOOKUP($E30,Viewpoint!$A:$E,5,FALSE)&"",""))) -> 同上 | G30: Nomal | H30: CM_B_12 | I30: 同上 | J30: 同上 | K30: OK | L30: 15-04-2025 | M30: DaiHM
A31: =IF(J31="","",ROW()-2) -> 29 | B31: =IFERROR(VLOOKUP($E31,Viewpoint!$A:$D,2,FALSE)&"","") | C31: =IFERROR(VLOOKUP($E31,Viewpoint!$A:$D,3,FALSE)&"","") | D31: =IFERROR(VLOOKUP($E31,Viewpoint_bk!$A:$D,4,FALSE)&"","") | E31: 2-2 | F31: =IF(E31="","",IF(E31=E30,"同上",IFERROR(VLOOKUP($E31,Viewpoint!$A:$E,5,FALSE)&"",""))) | G31: Nomal | H31: CM_B_10 | I31: 同上 | J31: 同上 | K31: NG | L31: 15-04-2025 | M31: DaiHM
A32: =IF(J32="","",ROW()-2) -> 30 | B32: =IFERROR(VLOOKUP($E32,Viewpoint!$A:$D,2,FALSE)&"","") | C32: =IFERROR(VLOOKUP($E32,Viewpoint!$A:$D,3,FALSE)&"","") | D32: =IFERROR(VLOOKUP($E32,Viewpoint_bk!$A:$D,4,FALSE)&"","") | E32: 2-2 | F32: =IF(E32="","",IF(E32=E31,"同上",IFERROR(VLOOKUP($E32,Viewpoint!$A:$E,5,FALSE)&"",""))) -> 同上 | G32: Nomal | H32: CM_B_11 | I32: 同上 | J32: 同上 | K32: NG | L32: 15-04-2025 | M32: DaiHM
A33: =IF(J33="","",ROW()-2) -> 31 | B33: =IFERROR(VLOOKUP($E33,Viewpoint!$A:$D,2,FALSE)&"","") | C33: =IFERROR(VLOOKUP($E33,Viewpoint!$A:$D,3,FALSE)&"","") | D33: =IFERROR(VLOOKUP($E33,Viewpoint_bk!$A:$D,4,FALSE)&"","") | E33: 2-2 | F33: =IF(E33="","",IF(E33=E32,"同上",IFERROR(VLOOKUP($E33,Viewpoint!$A:$E,5,FALSE)&"",""))) -> 同上 | G33: Nomal | H33: CM_B_12 | I33: 同上 | J33: 同上 | K33: NG | L33: 15-04-2025 | M33: DaiHM
A34: =IF(J34="","",ROW()-2) -> 32 | B34: =IFERROR(VLOOKUP($E34,Viewpoint!$A:$D,2,FALSE)&"","") | C34: =IFERROR(VLOOKUP($E34,Viewpoint!$A:$D,3,FALSE)&"","") | D34: =IFERROR(VLOOKUP($E34,Viewpoint_bk!$A:$D,4,FALSE)&"","") | E34: 4-1 | F34: =IF(E34="","",IF(E34=E6,"同上",IFERROR(VLOOKUP($E34,Viewpoint!$A:$E,5,FALSE)&"",""))) | G34: Nomal | H34: MM1_A_3 | I34: Tham chiếu sheet "Testcase_Meeting-Minutes" | J34: Tham chiếu sheet "Testcase_Meeting-Minutes" | K34: OK | L34: 15-04-2025 | M34: DaiHM
A35: =IF(J35="","",ROW()-2) -> 33 | B35: =IFERROR(VLOOKUP($E35,Viewpoint!$A:$D,2,FALSE)&"","") | C35: =IFERROR(VLOOKUP($E35,Viewpoint!$A:$D,3,FALSE)&"","") | D35: =IFERROR(VLOOKUP($E35,Viewpoint_bk!$A:$D,4,FALSE)&"","") | E35: 4-1 | F35: =IF(E35="","",IF(E35=E34,"同上",IFERROR(VLOOKUP($E35,Viewpoint!$A:$E,5,FALSE)&"",""))) -> 同上 | G35: Nomal | H35: MM1_A_7 | I35: 同上 | J35: 同上 | K35: OK | L35: 15-04-2025 | M35: DaiHM
A36: =IF(J36="","",ROW()-2) -> 34 | B36: =IFERROR(VLOOKUP($E36,Viewpoint!$A:$D,2,FALSE)&"","") | E36: 4-1 | F36: =IF(E36="","",IF(E36=E35,"同上",IFERROR(VLOOKUP($E36,Viewpoint!$A:$E,5,FALSE)&"",""))) -> 同上 | G36: Normal | H36: MM2_B_1 | I36: 同上 | J36: 同上 | K36: OK | L36: 15-04-2025 | M36: DaiHM
A37: =IF(J37="","",ROW()-2) -> 35 | B37: =IFERROR(VLOOKUP($E37,Viewpoint!$A:$D,2,FALSE)&"","") | C37: =IFERROR(VLOOKUP($E37,Viewpoint!$A:$D,3,FALSE)&"","") | D37: =IFERROR(VLOOKUP($E37,Viewpoint_bk!$A:$D,4,FALSE)&"","") | E37: 2-2 | F37: =IF(E37="","",IF(E37=E36,"同上",IFERROR(VLOOKUP($E37,Viewpoint!$A:$E,5,FALSE)&"",""))) | G37: Nomal | H37: MM3_D_2 | I37: 同上 | J37: 同上 | K37: OK | L37: 15-04-2025 | M37: DaiHM
A38: =IF(J38="","",ROW()-2) -> 36 | B38: =IFERROR(VLOOKUP($E38,Viewpoint!$A:$D,2,FALSE)&"","") | C38: =IFERROR(VLOOKUP($E38,Viewpoint!$A:$D,3,FALSE)&"","") | D38: =IFERROR(VLOOKUP($E38,Viewpoint_bk!$A:$D,4,FALSE)&"","") | E38: 2-2 | F38: =IF(E38="","",IF(E38=#REF!,"同上",IFERROR(VLOOKUP($E38,Viewpoint!$A:$E,5,FALSE)&"",""))) -> #REF! | G38: Nomal | H38: MM4_E_1 | I38: 同上 | J38: 同上 | K38: OK | L38: 15-04-2025 | M38: DaiHM
A39: =IF(J39="","",ROW()-2) -> 37 | B39: =IFERROR(VLOOKUP($E39,Viewpoint!$A:$D,2,FALSE)&"","") | E39: 2-2 | F39: =IF(E39="","",IF(E39=E38,"同上",IFERROR(VLOOKUP($E39,Viewpoint!$A:$E,5,FALSE)&"",""))) -> 同上 | G39: Nomal | H39: MM5_F_1 | I39: 同上 | J39: 同上 | K39: OK | L39: 15-04-2025 | M39: DaiHM
A40: =IF(J40="","",ROW()-2) -> 38 | B40: =IFERROR(VLOOKUP($E40,Viewpoint!$A:$D,2,FALSE)&"","") | E40: 2-2 | F40: =IF(E40="","",IF(E40=E39,"同上",IFERROR(VLOOKUP($E40,Viewpoint!$A:$E,5,FALSE)&"",""))) -> 同上 | G40: Nomal | H40: MM5_F_5 | I40: 同上 | J40: 同上 | K40: OK | L40: 15-04-2025 | M40: DaiHM
A41: =IF(J41="","",ROW()-2) -> 39 | B41: =IFERROR(VLOOKUP($E41,Viewpoint!$A:$D,2,FALSE)&"","") | E41: 4-1 | F41: =IF(E41="","",IF(E41=E40,"同上",IFERROR(VLOOKUP($E41,Viewpoint!$A:$E,5,FALSE)&"",""))) | G41: Nomal | H41: WP1_A_4 | I41: Tham chiếu sheet "Testcase_White-paper" | J41: Tham chiếu sheet "Testcase_White-paper" | K41: OK | L41: 15-04-2025 | M41: Trường
A42: =IF(J42="","",ROW()-2) -> 40 | B42: =IFERROR(VLOOKUP($E42,Viewpoint!$A:$D,2,FALSE)&"","") | E42: 4-1 | F42: =IF(E42="","",IF(E42=E41,"同上",IFERROR(VLOOKUP($E42,Viewpoint!$A:$E,5,FALSE)&"",""))) -> 同上 | G42: Nomal | H42: WP1_A_8 | I42: 同上 | J42: 同上 | K42: OK | L42: 15-04-2025 | M42: Trường
A43: =IF(J43="","",ROW()-2) -> 41 | B43: =IFERROR(VLOOKUP($E43,Viewpoint!$A:$D,2,FALSE)&"","") | E43: 2-2 | F43: =IF(E43="","",IF(E43=E42,"同上",IFERROR(VLOOKUP($E43,Viewpoint!$A:$E,5,FALSE)&"",""))) | G43: Nomal | H43: WP1_A_4_1 | I43: 同上 | J43: 同上 | K43: OK | L43: 15-04-2025 | M43: Trường
A44: =IF(J44="","",ROW()-2) -> 42 | B44: =IFERROR(VLOOKUP($E44,Viewpoint!$A:$D,2,FALSE)&"","") | E44: 2-2 | F44: =IF(E44="","",IF(E44=E43,"同上",IFERROR(VLOOKUP($E44,Viewpoint!$A:$E,5,FALSE)&"",""))) -> 同上 | G44: Nomal | H44: WP1_A_8_1 | I44: 同上 | J44: 同上 | K44: OK | L44: 15-04-2025 | M44: Trường
A45: =IF(J45="","",ROW()-2) -> 43 | B45: =IFERROR(VLOOKUP($E45,Viewpoint!$A:$D,2,FALSE)&"","") | E45: 2-2 | F45: =IF(E45="","",IF(E45=E44,"同上",IFERROR(VLOOKUP($E45,Viewpoint!$A:$E,5,FALSE)&"",""))) -> 同上 | G45: Nomal | H45: WP1_A_11 | I45: 同上 | J45: 同上 | K45: OK | L45: 15-04-2025 | M45: Trường
A46: =IF(J46="","",ROW()-2) -> 44 | B46: =IFERROR(VLOOKUP($E46,Viewpoint!$A:$D,2,FALSE)&"","") | E46: 2-2 | F46: =IF(E46="","",IF(E46=E45,"同上",IFERROR(VLOOKUP($E46,Viewpoint!$A:$E,5,FALSE)&"",""))) -> 同上 | G46: Nomal | H46: WP2_B_1 | I46: 同上 | J46: 同上 | K46: OK | L46: 15-04-2025 | M46: Trường
A47: =IF(J47="","",ROW()-2) -> 45 | B47: =IFERROR(VLOOKUP($E47,Viewpoint!$A:$D,2,FALSE)&"","") | E47: 2-2 | F47: =IF(E47="","",IF(E47=E46,"同上",IFERROR(VLOOKUP($E47,Viewpoint!$A:$E,5,FALSE)&"",""))) -> 同上 | G47: Nomal | H47: WP2_B_5 | I47: 同上 | J47: 同上 | K47: OK | L47: 15-04-2025 | M47: Trường
A48: =IF(J48="","",ROW()-2) -> 46 | B48: =IFERROR(VLOOKUP($E48,Viewpoint!$A:$D,2,FALSE)&"","") | E48: 4-1 | F48: =IF(E48="","",IF(E48=E47,"同上",IFERROR(VLOOKUP($E48,Viewpoint!$A:$E,5,FALSE)&"",""))) | G48: Nomal | H48: WP3_D_2 | I48: 同上 | J48: 同上 | K48: OK | L48: 15-04-2025 | M48: Trường
A49: =IF(J49="","",ROW()-2) -> 47 | B49: =IFERROR(VLOOKUP($E49,Viewpoint!$A:$D,2,FALSE)&"","") | E49: 2-2 | F49: =IF(E49="","",IF(E49=E48,"同上",IFERROR(VLOOKUP($E49,Viewpoint!$A:$E,5,FALSE)&"",""))) | G49: Nomal | H49: WP3_D_1 | I49: 同上 | J49: 同上 | K49: OK | L49: 15-04-2025 | M49: Trường
...
