Workbook

Sheet Cover
D1: TESTCASE DOCUMENTS
B3: Project Name: | D3: <Nhập tên dự án>A | E3: Reviewer: | G3: HaPT
B4: Phase: | D4: <Nhập phase dự án>3 | E4: Created time (h): | G4: ='Module 1'!E3+#REF!+#REF!+#REF!+#REF!+#REF!+#REF!
B6: Record of change: | H6: (*) A (Add), M (Modify), D (Delete)
B7: Date | C7: Version | D7: Change Description | E7: A, D, M (*) | F7: Change item | G7: Reference | H7: PIC

Sheet Report
D2: Round 1 | K2: Round 2 | R2: Round 3
A3: General statistic | D3: Pass | E3: Fail | F3: Untested | G3: Rejected | H3: Total | I3: % coverage | J3: Pass coverage | K3: Pass | L3: Fail | M3: Untested | N3: Rejected | O3: Total | P3: % coverage | Q3: Pass coverage | R3: Pass | S3: Fail | T3: Untested | U3: Rejected | V3: Total | W3: % coverage | X3: Pass coverage
A4: Environment | C4: ENV 1A | D4: =D15+I15+N15 | E4: =E15+J15+O15 | F4: =F15+K15+P15 | G4: =G15+L15+Q15 | H4: =H15+M15+R15 | I4: =ROUND(100*(D4+E4)/(H4-G4),2) | J4: =ROUND(100*D4/(H4-G4),2) | K4: =D27+I27+N27 | L4: =E27+J27+O27 | M4: =F27+K27+P27 | N4: =G27+L27+Q27 | O4: =H27+M27+R27 | P4: =ROUND(100*(K4+L4)/(O4-N4),2) | Q4: =ROUND(100*K4/(O4-N4),2) | R4: =D39+I39+N39 | S4: =E39+J39+O39 | T4: =F39+K39+P39 | U4: =G39+L39+Q39 | V4: =H39+M39+R39 | W4: =ROUND(100*(R4+S4)/(V4-U4),2) | X4: =ROUND(100*R4/(V4-U4),2)
C5: ENV 2B | D5: =D16+I16+N16 | E5: =E16+J16+O16 | F5: =F16+K16+P16 | G5: =G16+L16+Q16 | H5: =H16+M16+R16 | I5: =ROUND(100*(D5+E5)/(H5-G5),2) | J5: =ROUND(100*D5/(H5-G5),2) | K5: =D28+I28+N28 | L5: =E28+J28+O28 | M5: =F28+K28+P28 | N5: =G28+L28+Q28 | O5: =H28+M28+R28 | P5: =ROUND(100*(K5+L5)/(O5-N5),2) | Q5: =ROUND(100*K5/(O5-N5),2) | R5: =D40+I40+N40 | S5: =E40+J40+O40 | T5: =F40+K40+P40 | U5: =G40+L40+Q40 | V5: =H40+M40+R40 | W5: =ROUND(100*(R5+S5)/(V5-U5),2) | X5: =ROUND(100*R5/(V5-U5),2)
C6: ENV 3C | D6: =D17+I17+N17 | E6: =E17+J17+O17 | F6: =F17+K17+P17 | G6: =G17+L17+Q17 | H6: =H17+M17+R17 | I6: =ROUND(100*(D6+E6)/(H6-G6),2) | J6: =ROUND(100*D6/(H6-G6),2) | K6: =D29+I29+N29 | L6: =E29+J29+O29 | M6: =F29+K29+P29 | N6: =G29+L29+Q29 | O6: =H29+M29+R29 | P6: =ROUND(100*(K6+L6)/(O6-N6),2) | Q6: =ROUND(100*K6/(O6-N6),2) | R6: =D41+I41+N41 | S6: =E41+J41+O41 | T6: =F41+K41+P41 | U6: =G41+L41+Q41 | V6: =H41+M41+R41 | W6: =ROUND(100*(R6+S6)/(V6-U6),2) | X6: =ROUND(100*R6/(V6-U6),2)
C7: ENV 4D | D7: =D18+I18+N18 | E7: =E18+J18+O18 | F7: =F18+K18+P18 | G7: =G18+L18+Q18 | H7: =H18+M18+R18 | I7: =ROUND(100*(D7+E7)/(H7-G7),2) | J7: =ROUND(100*D7/(H7-G7),2) | K7: =D30+I30+N30 | L7: =E30+J30+O30 | M7: =F30+K30+P30 | N7: =G30+L30+Q30 | O7: =H30+M30+R30 | P7: =ROUND(100*(K7+L7)/(O7-N7),2) | Q7: =ROUND(100*K7/(O7-N7),2) | R7: =D42+I42+N42 | S7: =E42+J42+O42 | T7: =F42+K42+P42 | U7: =G42+L42+Q42 | V7: =H42+M42+R42 | W7: =ROUND(100*(R7+S7)/(V7-U7),2) | X7: =ROUND(100*R7/(V7-U7),2)
C8: ENV 5E | D8: =D19+I19+N19 | E8: =E19+J19+O19 | F8: =F19+K19+P19 | G8: =G19+L19+Q19 | H8: =H19+M19+R19 | I8: =ROUND(100*(D8+E8)/(H8-G8),2) | J8: =ROUND(100*D8/(H8-G8),2) | K8: =D31+I31+N31 | L8: =E31+J31+O31 | M8: =F31+K31+P31 | N8: =G31+L31+Q31 | O8: =H31+M31+R31 | P8: =ROUND(100*(K8+L8)/(O8-N8),2) | Q8: =ROUND(100*K8/(O8-N8),2) | R8: =D43+I43+N43 | S8: =E43+J43+O43 | T8: =F43+K43+P43 | U8: =G43+L43+Q43 | V8: =H43+M43+R43 | W8: =ROUND(100*(R8+S8)/(V8-U8),2) | X8: =ROUND(100*R8/(V8-U8),2)
C9: ENV 6F | D9: =D20+I20+N20 | E9: =E20+J20+O20 | F9: =F20+K20+P20 | G9: =G20+L20+Q20 | H9: =H20+M20+R20 | I9: =ROUND(100*(D9+E9)/(H9-G9),2) | J9: =ROUND(100*D9/(H9-G9),2) | K9: =D32+I32+N32 | L9: =E32+J32+O32 | M9: =F32+K32+P32 | N9: =G32+L32+Q32 | O9: =H32+M32+R32 | P9: =ROUND(100*(K9+L9)/(O9-N9),2) | Q9: =ROUND(100*K9/(O9-N9),2) | R9: =D44+I44+N44 | S9: =E44+J44+O44 | T9: =F44+K44+P44 | U9: =G44+L44+Q44 | V9: =H44+M44+R44 | W9: =ROUND(100*(R9+S9)/(V9-U9),2) | X9: =ROUND(100*R9/(V9-U9),2)
A11: Round base statistic
A12: Round 1 | D12: Test result | S12: Test coverage (%) | V12: Pass coverage (%)
D13: High | I13: Normal | N13: Low | S13: High | T13: Normal | U13: Low | V13: High | W13: Normal | X13: Low
D14: Pass | E14: Fail | F14: Untested | G14: Rejected | H14: Total | I14: Pass | J14: Fail | K14: Untested | L14: Rejected | M14: Total | N14: Pass | O14: Fail | P14: Untested | Q14: Rejected | R14: Total
A15: Environment | C15: =C4 | D15: =SUMIF(C49:C94,C15,D49:D94) | E15: =SUMIF(C49:C94,C15,E49:E94) | F15: =SUMIF(C49:C94,C15,F49:F94) | G15: =SUMIF(C49:C94,C15,G49:G94) | H15: =SUMIF(C49:C94,C15,H49:H94) | I15: =SUMIF(C49:C94,C15,I49:I94) | J15: =SUMIF(C49:C94,C15,J49:J94) | K15: =SUMIF(C49:C94,C15,K49:K94) | L15: =SUMIF(C49:C94,C15,L49:L94) | M15: =SUMIF(C49:C94,C15,M49:M94) | N15: =SUMIF(C49:C94,C15,N49:N94) | O15: =SUMIF(C49:C94,C15,O49:O94) | P15: =SUMIF(C49:C94,C15,P49:P94) | Q15: =SUMIF(C49:C94,C15,Q49:Q94) | R15: =SUMIF(C49:C94,C15,R49:R94) | S15: =(D15+E15)*100/(H15-G15) | T15: =(I15+J15)*100/(M15-L15) | U15: =(N15+O15)*100/(R15-Q15) | V15: =D15*100/(H15-G15) | W15: =I15*100/(M15-L15) | X15: =N15*100/(R15-Q15)
C16: =C5 | D16: =SUMIF(C49:C94,C16,D49:D94) | E16: =SUMIF(C49:C94,C16,E49:E94) | F16: =SUMIF(C49:C94,C16,F49:F94) | G16: =SUMIF(C49:C94,C16,G49:G94) | H16: =SUMIF(C49:C94,C16,H49:H94) | I16: =SUMIF(C49:C94,C16,I49:I94) | J16: =SUMIF(C49:C94,C16,J49:J94) | K16: =SUMIF(C49:C94,C16,K49:K94) | L16: =SUMIF(C49:C94,C16,L49:L94) | M16: =SUMIF(C49:C94,C16,M49:M94) | N16: =SUMIF(C49:C94,C16,N49:N94) | O16: =SUMIF(C49:C94,C16,O49:O94) | P16: =SUMIF(C49:C94,C16,P49:P94) | Q16: =SUMIF(C49:C94,C16,Q49:Q94) | R16: =SUMIF(C49:C94,C16,R49:R94) | S16: =(D16+E16)*100/(H16-G16) | T16: =(I16+J16)*100/(M16-L16) | U16: =(N16+O16)*100/(R16-Q16) | V16: =D16*100/(H16-G16) | W16: =I16*100/(M16-L16) | X16: =N16*100/(R16-Q16)
C17: =C6 | D17: =SUMIF(C49:C94,C17,D49:D94) | E17: =SUMIF(C49:C94,C17,E49:E94) | F17: =SUMIF(C49:C94,C17,F49:F94) | G17: =SUMIF(C49:C94,C17,G49:G94) | H17: =SUMIF(C49:C94,C17,H49:H94) | I17: =SUMIF(C49:C94,C17,I49:I94) | J17: =SUMIF(C49:C94,C17,J49:J94) | K17: =SUMIF(C49:C94,C17,K49:K94) | L17: =SUMIF(C49:C94,C17,L49:L94) | M17: =SUMIF(C49:C94,C17,M49:M94) | N17: =SUMIF(C49:C94,C17,N49:N94) | O17: =SUMIF(C49:C94,C17,O49:O94) | P17: =SUMIF(C49:C94,C17,P49:P94) | Q17: =SUMIF(C49:C94,C17,Q49:Q94) | R17: =SUMIF(C49:C94,C17,R49:R94) | S17: =(D17+E17)*100/(H17-G17) | T17: =(I17+J17)*100/(M17-L17) | U17: =(N17+O17)*100/(R17-Q17) | V17: =D17*100/(H17-G17) | W17: =I17*100/(M17-L17) | X17: =N17*100/(R17-Q17)
C18: =C7 | D18: =SUMIF(C49:C94,C18,D49:D94) | E18: =SUMIF(C49:C94,C18,E49:E94) | F18: =SUMIF(C49:C94,C18,F49:F94) | G18: =SUMIF(C49:C94,C18,G49:G94) | H18: =SUMIF(C49:C94,C18,H49:H94) | I18: =SUMIF(C49:C94,C18,I49:I94) | J18: =SUMIF(C49:C94,C18,J49:J94) | K18: =SUMIF(C49:C94,C18,K49:K94) | L18: =SUMIF(C49:C94,C18,L49:L94) | M18: =SUMIF(C49:C94,C18,M49:M94) | N18: =SUMIF(C49:C94,C18,N49:N94) | O18: =SUMIF(C49:C94,C18,O49:O94) | P18: =SUMIF(C49:C94,C18,P49:P94) | Q18: =SUMIF(C49:C94,C18,Q49:Q94) | R18: =SUMIF(C49:C94,C18,R49:R94) | S18: =(D18+E18)*100/(H18-G18) | T18: =(I18+J18)*100/(M18-L18) | U18: =(N18+O18)*100/(R18-Q18) | V18: =D18*100/(H18-G18) | W18: =I18*100/(M18-L18) | X18: =N18*100/(R18-Q18)
C19: =C8 | D19: =SUMIF(C49:C94,C19,D49:D94) | E19: =SUMIF(C49:C94,C19,E49:E94) | F19: =SUMIF(C49:C94,C19,F49:F94) | G19: =SUMIF(C49:C94,C19,G49:G94) | H19: =SUMIF(C49:C94,C19,H49:H94) | I19: =SUMIF(C49:C94,C19,I49:I94) | J19: =SUMIF(C49:C94,C19,J49:J94) | K19: =SUMIF(C49:C94,C19,K49:K94) | L19: =SUMIF(C49:C94,C19,L49:L94) | M19: =SUMIF(C49:C94,C19,M49:M94) | N19: =SUMIF(C49:C94,C19,N49:N94) | O19: =SUMIF(C49:C94,C19,O49:O94) | P19: =SUMIF(C49:C94,C19,P49:P94) | Q19: =SUMIF(C49:C94,C19,Q49:Q94) | R19: =SUMIF(C49:C94,C19,R49:R94) | S19: =(D19+E19)*100/(H19-G19) | T19: =(I19+J19)*100/(M19-L19) | U19: =(N19+O19)*100/(R19-Q19) | V19: =D19*100/(H19-G19) | W19: =I19*100/(M19-L19) | X19: =N19*100/(R19-Q19)
C20: =C9 | D20: =SUMIF(C49:C94,C20,D49:D94) | E20: =SUMIF(C49:C94,C20,E49:E94) | F20: =SUMIF(C49:C94,C20,F49:F94) | G20: =SUMIF(C49:C94,C20,G49:G94) | H20: =SUMIF(C49:C94,C20,H49:H94) | I20: =SUMIF(C49:C94,C20,I49:I94) | J20: =SUMIF(C49:C94,C20,J49:J94) | K20: =SUMIF(C49:C94,C20,K49:K94) | L20: =SUMIF(C49:C94,C20,L49:L94) | M20: =SUMIF(C49:C94,C20,M49:M94) | N20: =SUMIF(C49:C94,C20,N49:N94) | O20: =SUMIF(C49:C94,C20,O49:O94) | P20: =SUMIF(C49:C94,C20,P49:P94) | Q20: =SUMIF(C49:C94,C20,Q49:Q94) | R20: =SUMIF(C49:C94,C20,R49:R94) | S20: =(D20+E20)*100/(H20-G20) | T20: =(I20+J20)*100/(M20-L20) | U20: =(N20+O20)*100/(R20-Q20) | V20: =D20*100/(H20-G20) | W20: =I20*100/(M20-L20) | X20: =N20*100/(R20-Q20)
A21: Total: | D21: =SUM(D15:D20) | E21: =SUM(E15:E20) | F21: =SUM(F15:F20) | G21: =SUM(G15:G20) | H21: =SUM(H15:H20) | I21: =SUM(I15:I20) | J21: =SUM(J15:J20) | K21: =SUM(K15:K20) | ... R21: =SUM(R15:R20) | S21: =SUM(S15:S20)/COUNTA(C15:C20) | T21: =SUM(T15:T20)/COUNTA(C15:C20) | U21: =SUM(U15:U20)/COUNTA(C15:C20) | V21: =SUM(V15:V20)/COUNTA(C15:C20) | W21: =SUM(W15:W20)/COUNTA(C15:C20) | X21: =SUM(X15:X20)/COUNTA(C15:C20)
A24: Round 2 | D24: Test result | S24: Test coverage (%) | V24: Pass coverage (%)
D25: High | I25: Normal | N25: Low | S25: =S13 | T25: =T13 | U25: =U13 | V25: =V13 | W25: =W13 | X25: =X13
D26: =D14 | E26: =E14 | F26: =F14 | G26: =G14 | H26: =H14 | I26: =I14 | J26: =J14 | K26: =K14 | ... R26: =R14
A27: Environment | C27: =C4 | D27: =SUMIF(C97:C142,C15,D97:D142) | E27: =SUMIF(C97:C142,C15,E97:E142) | F27: =SUMIF(C97:C142,C15,F97:F142) | G27: =SUMIF(C97:C142,C15,G97:G142) | H27: =SUMIF(C97:C142,C15,H97:H142) | I27: =SUMIF(C97:C142,C15,I97:I142) | J27: =SUMIF(C97:C142,C15,J97:J142) | K27: =SUMIF(C97:C142,C15,K97:K142) | L27: =SUMIF(C97:C142,C15,L97:L142) | M27: =SUMIF(C97:C142,C15,M97:M142) | N27: =SUMIF(C97:C142,C15,N97:N142) | O27: =SUMIF(C97:C142,C15,O97:O142) | P27: =SUMIF(C97:C142,C15,P97:P142) | Q27: =SUMIF(C97:C142,C15,Q97:Q142) | R27: =SUMIF(C97:C142,C15,R97:R142) | S27: =(D27+E27)*100/(H27-G27) | T27: =(I27+J27)*100/(M27-L27) | U27: =(N27+O27)*100/(R27-Q27) | V27: =D27*100/(H27-G27) | W27: =I27*100/(M27-L27) | X27: =N27*100/(R27-Q27)
C28: =C5 | D28: =SUMIF(C97:C142,C16,D97:D142) | E28: =SUMIF(C97:C142,C16,E97:E142) | F28: =SUMIF(C97:C142,C16,F97:F142) | G28: =SUMIF(C97:C142,C16,G97:G142) | H28: =SUMIF(C97:C142,C16,H97:H142) | I28: =SUMIF(C97:C142,C16,I97:I142) | J28: =SUMIF(C97:C142,C16,J97:J142) | K28: =SUMIF(C97:C142,C16,K97:K142) | L28: =SUMIF(C97:C142,C16,L97:L142) | M28: =SUMIF(C97:C142,C16,M97:M142) | N28: =SUMIF(C97:C142,C16,N97:N142) | O28: =SUMIF(C97:C142,C16,O97:O142) | P28: =SUMIF(C97:C142,C16,P97:P142) | Q28: =SUMIF(C97:C142,C16,Q97:Q142) | R28: =SUMIF(C97:C142,C16,R97:R142) | S28: =(D28+E28)*100/(H28-G28) | T28: =(I28+J28)*100/(M28-L28) | U28: =(N28+O28)*100/(R28-Q28) | V28: =D28*100/(H28-G28) | W28: =I28*100/(M28-L28) | X28: =N28*100/(R28-Q28)
C29: =C6 | D29: =SUMIF(C97:C142,C17,D97:D142) | E29: =SUMIF(C97:C142,C17,E97:E142) | F29: =SUMIF(C97:C142,C17,F97:F142) | G29: =SUMIF(C97:C142,C17,G97:G142) | H29: =SUMIF(C97:C142,C17,H97:H142) | I29: =SUMIF(C97:C142,C17,I97:I142) | J29: =SUMIF(C97:C142,C17,J97:J142) | K29: =SUMIF(C97:C142,C17,K97:K142) | L29: =SUMIF(C97:C142,C17,L97:L142) | M29: =SUMIF(C97:C142,C17,M97:M142) | N29: =SUMIF(C97:C142,C17,N97:N142) | O29: =SUMIF(C97:C142,C17,O97:O142) | P29: =SUMIF(C97:C142,C17,P97:P142) | Q29: =SUMIF(C97:C142,C17,Q97:Q142) | R29: =SUMIF(C97:C142,C17,R97:R142) | S29: =(D29+E29)*100/(H29-G29) | T29: =(I29+J29)*100/(M29-L29) | U29: =(N29+O29)*100/(R29-Q29) | V29: =D29*100/(H29-G29) | W29: =I29*100/(M29-L29) | X29: =N29*100/(R29-Q29)
C30: =C7 | D30: =SUMIF(C97:C142,C18,D97:D142) | E30: =SUMIF(C97:C142,C18,E97:E142) | F30: =SUMIF(C97:C142,C18,F97:F142) | G30: =SUMIF(C97:C142,C18,G97:G142) | H30: =SUMIF(C97:C142,C18,H97:H142) | I30: =SUMIF(C97:C142,C18,I97:I142) | J30: =SUMIF(C97:C142,C18,J97:J142) | K30: =SUMIF(C97:C142,C18,K97:K142) | L30: =SUMIF(C97:C142,C18,L97:L142) | M30: =SUMIF(C97:C142,C18,M97:M142) | N30: =SUMIF(C97:C142,C18,N97:N142) | O30: =SUMIF(C97:C142,C18,O97:O142) | P30: =SUMIF(C97:C142,C18,P97:P142) | Q30: =SUMIF(C97:C142,C18,Q97:Q142) | R30: =SUMIF(C97:C142,C18,R97:R142) | S30: =(D30+E30)*100/(H30-G30) | T30: =(I30+J30)*100/(M30-L30) | U30: =(N30+O30)*100/(R30-Q30) | V30: =D30*100/(H30-G30) | W30: =I30*100/(M30-L30) | X30: =N30*100/(R30-Q30)
C31: =C8 | D31: =SUMIF(C97:C142,C19,D97:D142) | E31: =SUMIF(C97:C142,C19,E97:E142) | F31: =SUMIF(C97:C142,C19,F97:F142) | G31: =SUMIF(C97:C142,C19,G97:G142) | H31: =SUMIF(C97:C142,C19,H97:H142) | I31: =SUMIF(C97:C142,C19,I97:I142) | J31: =SUMIF(C97:C142,C19,J97:J142) | K31: =SUMIF(C97:C142,C19,K97:K142) | L31: =SUMIF(C97:C142,C19,L97:L142) | M31: =SUMIF(C97:C142,C19,M97:M142) | N31: =SUMIF(C97:C142,C19,N97:N142) | O31: =SUMIF(C97:C142,C19,O97:O142) | P31: =SUMIF(C97:C142,C19,P97:P142) | Q31: =SUMIF(C97:C142,C19,Q97:Q142) | R31: =SUMIF(C97:C142,C19,R97:R142) | S31: =(D31+E31)*100/(H31-G31) | T31: =(I31+J31)*100/(M31-L31) | U31: =(N31+O31)*100/(R31-Q31) | V31: =D31*100/(H31-G31) | W31: =I31*100/(M31-L31) | X31: =N31*100/(R31-Q31)
C32: =C9 | D32: =SUMIF(C97:C142,C20,D97:D142) | E32: =SUMIF(C97:C142,C20,E97:E142) | F32: =SUMIF(C97:C142,C20,F97:F142) | G32: =SUMIF(C97:C142,C20,G97:G142) | H32: =SUMIF(C97:C142,C20,H97:H142) | I32: =SUMIF(C97:C142,C20,I97:I142) | J32: =SUMIF(C97:C142,C20,J97:J142) | K32: =SUMIF(C97:C142,C20,K97:K142) | L32: =SUMIF(C97:C142,C20,L97:L142) | M32: =SUMIF(C97:C142,C20,M97:M142) | N32: =SUMIF(C97:C142,C20,N97:N142) | O32: =SUMIF(C97:C142,C20,O97:O142) | P32: =SUMIF(C97:C142,C20,P97:P142) | Q32: =SUMIF(C97:C142,C20,Q97:Q142) | R32: =SUMIF(C97:C142,C20,R97:R142) | S32: =(D32+E32)*100/(H32-G32) | T32: =(I32+J32)*100/(M32-L32) | U32: =(N32+O32)*100/(R32-Q32) | V32: =D32*100/(H32-G32) | W32: =I32*100/(M32-L32) | X32: =N32*100/(R32-Q32)
A33: Total: | D33: =SUM(D27:D32) | E33: =SUM(E27:E32) | F33: =SUM(F27:F32) | G33: =SUM(G27:G32) | H33: =SUM(H27:H32) | I33: =SUM(I27:I32) | J33: =SUM(J27:J32) | K33: =SUM(K27:K32) | ... R33: =SUM(R27:R32) | S33: =SUM(S27:S32)/COUNTA(C15:C20) | T33: =SUM(T27:T32)/COUNTA(C15:C20) | U33: =SUM(U27:U32)/COUNTA(C15:C20) | V33: =SUM(V27:V32)/COUNTA(C15:C20) | W33: =SUM(W27:W32)/COUNTA(C15:C20) | X33: =SUM(X27:X32)/COUNTA(C15:C20)
A36: Round 3 | D36: Test result | S36: Test coverage (%) | V36: Pass coverage (%)
D37: High | I37: Normal | N37: Low | S37: High | T37: Normal | U37: Low | V37: High | W37: Normal | X37: Low
D38: Pass | E38: Fail | F38: Untested | G38: Rejected | H38: Total | I38: Pass | J38: Fail | K38: Untested | L38: Rejected | M38: Total | N38: Pass | O38: Fail | P38: Untested | Q38: Rejected | R38: Total
A39: Environment | C39: =C4 | D39: =SUMIF(C145:C189,C15,D145:D189) | E39: =SUMIF(C145:C189,C15,E145:E189) | F39: =SUMIF(C145:C189,C15,F145:F189) | G39: =SUMIF(C145:C189,C15,G145:G189) | H39: =SUMIF(C145:C189,C15,H145:H189) | I39: =SUMIF(C145:C189,C15,I145:I189) | J39: =SUMIF(C145:C189,C15,J145:J189) | K39: =SUMIF(C145:C189,C15,K145:K189) | L39: =SUMIF(C145:C189,C15,L145:L189) | M39: =SUMIF(C145:C189,C15,M145:M189) | N39: =SUMIF(C145:C189,C15,N145:N189) | O39: =SUMIF(C145:C189,C15,O145:O189) | P39: =SUMIF(C145:C189,C15,P145:P189) | Q39: =SUMIF(C145:C189,C15,Q145:Q189) | R39: =SUMIF(C145:C189,C15,R145:R189) | S39: =(D39+E39)*100/(H39-G39) | T39: =(I39+J39)*100/(M39-L39) | U39: =(N39+O39)*100/(R39-Q39) | V39: =D39*100/(H39-G39) | W39: =I39*100/(M39-L39) | X39: =N39*100/(R39-Q39)
C40: =C5 | D40: =SUMIF(C145:C189,C16,D145:D189) | E40: =SUMIF(C145:C189,C16,E145:E189) | F40: =SUMIF(C145:C189,C16,F145:F189) | G40: =SUMIF(C145:C189,C16,G145:G189) | H40: =SUMIF(C145:C189,C16,H145:H189) | I40: =SUMIF(C145:C189,C16,I145:I189) | J40: =SUMIF(C145:C189,C16,J145:J189) | K40: =SUMIF(C145:C189,C16,K145:K189) | L40: =SUMIF(C145:C189,C16,L145:L189) | M40: =SUMIF(C145:C189,C16,M145:M189) | N40: =SUMIF(C145:C189,C16,N145:N189) | O40: =SUMIF(C145:C189,C16,O145:O189) | P40: =SUMIF(C145:C189,C16,P145:P189) | Q40: =SUMIF(C145:C189,C16,Q145:Q189) | R40: =SUMIF(C145:C189,C16,R145:R189) | S40: =(D40+E40)*100/(H40-G40) | T40: =(I40+J40)*100/(M40-L40) | U40: =(N40+O40)*100/(R40-Q40) | V40: =D40*100/(H40-G40) | W40: =I40*100/(M40-L40) | X40: =N40*100/(R40-Q40)
C41: =C6 | D41: =SUMIF(C145:C189,C17,D145:D189) | E41: =SUMIF(C145:C189,C17,E145:E189) | F41: =SUMIF(C145:C189,C17,F145:F189) | G41: =SUMIF(C145:C189,C17,G145:G189) | H41: =SUMIF(C145:C189,C17,H145:H189) | I41: =SUMIF(C145:C189,C17,I145:I189) | J41: =SUMIF(C145:C189,C17,J145:J189) | K41: =SUMIF(C145:C189,C17,K145:K189) | L41: =SUMIF(C145:C189,C17,L145:L189) | M41: =SUMIF(C145:C189,C17,M145:M189) | N41: =SUMIF(C145:C189,C17,N145:N189) | O41: =SUMIF(C145:C189,C17,O145:O189) | P41: =SUMIF(C145:C189,C17,P145:P189) | Q41: =SUMIF(C145:C189,C17,Q145:Q189) | R41: =SUMIF(C145:C189,C17,R145:R189) | S41: =(D41+E41)*100/(H41-G41) | T41: =(I41+J41)*100/(M41-L41) | U41: =(N41+O41)*100/(R41-Q41) | V41: =D41*100/(H41-G41) | W41: =I41*100/(M41-L41) | X41: =N41*100/(R41-Q41)
C42: =C7 | D42: =SUMIF(C145:C189,C18,D145:D189) | E42: =SUMIF(C145:C189,C18,E145:E189) | F42: =SUMIF(C145:C189,C18,F145:F189) | G42: =SUMIF(C145:C189,C18,G145:G189) | H42: =SUMIF(C145:C189,C18,H145:H189) | I42: =SUMIF(C145:C189,C18,I145:I189) | J42: =SUMIF(C145:C189,C18,J145:J189) | K42: =SUMIF(C145:C189,C18,K145:K189) | L42: =SUMIF(C145:C189,C18,L145:L189) | M42: =SUMIF(C145:C189,C18,M145:M189) | N42: =SUMIF(C145:C189,C18,N145:N189) | O42: =SUMIF(C145:C189,C18,O145:O189) | P42: =SUMIF(C145:C189,C18,P145:P189) | Q42: =SUMIF(C145:C189,C18,Q145:Q189) | R42: =SUMIF(C145:C189,C18,R145:R189) | S42: =(D42+E42)*100/(H42-G42) | T42: =(I42+J42)*100/(M42-L42) | U42: =(N42+O42)*100/(R42-Q42) | V42: =D42*100/(H42-G42) | W42: =I42*100/(M42-L42) | X42: =N42*100/(R42-Q42)
C43: =C8 | D43: =SUMIF(C145:C189,C19,D145:D189) | E43: =SUMIF(C145:C189,C19,E145:E189) | F43: =SUMIF(C145:C189,C19,F145:F189) | G43: =SUMIF(C145:C189,C19,G145:G189) | H43: =SUMIF(C145:C189,C19,H145:H189) | I43: =SUMIF(C145:C189,C19,I145:I189) | J43: =SUMIF(C145:C189,C19,J145:J189) | K43: =SUMIF(C145:C189,C19,K145:K189) | L43: =SUMIF(C145:C189,C19,L145:L189) | M43: =SUMIF(C145:C189,C19,M145:M189) | N43: =SUMIF(C145:C189,C19,N145:N189) | O43: =SUMIF(C145:C189,C19,O145:O189) | P43: =SUMIF(C145:C189,C19,P145:P189) | Q43: =SUMIF(C145:C189,C19,Q145:Q189) | R43: =SUMIF(C145:C189,C19,R145:R189) | S43: =(D43+E43)*100/(H43-G43) | T43: =(I43+J43)*100/(M43-L43) | U43: =(N43+O43)*100/(R43-Q43) | V43: =D43*100/(H43-G43) | W43: =I43*100/(M43-L43) | X43: =N43*100/(R43-Q43)
C44: =C9 | D44: =SUMIF(C145:C189,C20,D145:D189) | E44: =SUMIF(C145:C189,C20,E145:E189) | F44: =SUMIF(C145:C189,C20,F145:F189) | G44: =SUMIF(C145:C189,C20,G145:G189) | H44: =SUMIF(C145:C189,C20,H145:H189) | I44: =SUMIF(C145:C189,C20,I145:I189) | J44: =SUMIF(C145:C189,C20,J145:J189) | K44: =SUMIF(C145:C189,C20,K145:K189) | L44: =SUMIF(C145:C189,C20,L145:L189) | M44: =SUMIF(C145:C189,C20,M145:M189) | N44: =SUMIF(C145:C189,C20,N145:N189) | O44: =SUMIF(C145:C189,C20,O145:O189) | P44: =SUMIF(C145:C189,C20,P145:P189) | Q44: =SUMIF(C145:C189,C20,Q145:Q189) | R44: =SUMIF(C145:C189,C20,R145:R189) | S44: =(D44+E44)*100/(H44-G44) | T44: =(I44+J44)*100/(M44-L44) | U44: =(N44+O44)*100/(R44-Q44) | V44: =D44*100/(H44-G44) | W44: =I44*100/(M44-L44) | X44: =N44*100/(R44-Q44)
A45: Total: | D45: =SUM(D39:D44) | E45: =SUM(E39:E44) | F45: =SUM(F39:F44) | G45: =SUM(G39:G44) | H45: =SUM(H39:H44) | I45: =SUM(I39:I44) | J45: =SUM(J39:J44) | K45: =SUM(K39:K44) | ... R45: =SUM(R39:R44) | S45: =SUM(S39:S44)/COUNTA(C15:C20) | T45: =SUM(T39:T44)/COUNTA(C15:C20) | U45: =SUM(U39:U44)/COUNTA(C15:C20) | V45: =SUM(V39:V44)/COUNTA(C15:C20) | W45: =SUM(W39:W44)/COUNTA(C15:C20) | X45: =SUM(X39:X44)/COUNTA(C15:C20)
A47: Round 1 in detail
...

Sheet Module 1
A1: Module: | B1: MODULE-NAME | D1: Creator: | G1: Environment | H1: Priority | L1: Round 1 | R1: Round 2 | X1: Round 3
A2: Project name: | B2: =Cover!D3 | D2: Created date: | H2: High | I2: Normal | J2: Low | K2: Total | L2: Pass | M2: Fail | N2: Untested | O2: Rejected | P2: % coverage | Q2: Pass coverage | R2: Pass | S2: Fail | T2: Untested | U2: Rejected | V2: % coverage | W2: Pass coverage | X2: Pass | Y2: Fail | Z2: Untested | AA2: Rejected | AB2: % coverage | AC2: Pass coverage
A3: Phase: | B3: =Cover!D4 | D3: Created time: | E3: 0 | G3: =Report!C4 | H3: =COUNTIF(H12:H10000,"High") | I3: =COUNTIF(H12:H10000,"Normal") | J3: =COUNTIF(H12:H10000,"Low") | K3: =SUM(H3:J3) | L3: =COUNTIF(J12:J10000,"Pass") | M3: =COUNTIF(J12:J10000,"Fail") | N3: =$K$3-L3-M3-O3 | O3: =COUNTIF(J12:J10000,"Rejected") | P3: =(L3+M3)/($K$3-O3) | Q3: =L3/$K$3 | R3: =COUNTIF(AC12:AC10000,"Pass") | S3: =COUNTIF(AC12:AC10000,"Fail") | T3: =$K$3-R3-S3-U3 | U3: =COUNTIF(AC12:AC10000,"Rejected") | V3: =(R3+S3)/($K$3-U3) | W3: =R3/$K$3 | X3: =COUNTIF(AV12:AV10000,"Pass") | Y3: =COUNTIF(AV12:AV10000,"Fail") | Z3: =$K$3-X3-Y3-AA3 | AA3: =COUNTIF(AV12:AV10000,"Rejected") | AB3: =(X3+Y3)/($K$3-AA3) | AC3: =X3/$K$3
G4: =Report!C5 | L4: =COUNTIF(M12:M10000,"Pass") | M4: =COUNTIF(M12:M10000,"Fail") | N4: =$K$3-L4-M4-O4 | O4: =COUNTIF(M12:M10000,"Rejected") | P4: =(L4+M4)/($K$3-O4) | Q4: =L4/$K$3 | R4: =COUNTIF(AF12:AF10000,"Pass") | S4: =COUNTIF(AF12:AF10000,"Fail") | T4: =$K$3-R4-S4-U4 | U4: =COUNTIF(AF12:AF10000,"Rejected") | V4: =(R4+S4)/($K$3-U4) | W4: =R4/$K$3 | X4: =COUNTIF(AY12:AY10000,"Pass") | Y4: =COUNTIF(AY12:AY10000,"Fail") | Z4: =$K$3-X4-Y4-AA4 | AA4: =COUNTIF(AY12:AY10000,"Rejected") | AB4: =(X4+Y4)/($K$3-AA4) | AC4: =X4/$K$3
G5: =Report!C6 | L5: =COUNTIF(P12:P10000,"Pass") | M5: =COUNTIF(P12:P10000,"Fail") | N5: =$K$3-L5-M5-O5 | O5: =COUNTIF(P12:P10000,"Rejected") | P5: =(L5+M5)/($K$3-O5) | Q5: =L5/$K$3 | R5: =COUNTIF(AI12:AI10000,"Pass") | S5: =COUNTIF(AI12:AI10000,"Fail") | T5: =$K$3-R5-S5-U5 | U5: =COUNTIF(AI12:AI10000,"Rejected") | V5: =(R5+S5)/($K$3-U5) | W5: =R5/$K$3 | X5: =COUNTIF(BB12:BB10000,"Pass") | Y5: =COUNTIF(BB12:BB10000,"Fail") | Z5: =$K$3-X5-Y5-AA5 | AA5: =COUNTIF(BB12:BB10000,"Rejected") | AB5: =(X5+Y5)/($K$3-AA5) | AC5: =X5/$K$3
G6: =Report!C7 | L6: =COUNTIF(S12:S10000,"Pass") | M6: =COUNTIF(S12:S10000,"Fail") | N6: =$K$3-L6-M6-O6 | O6: =COUNTIF(S12:S10000,"Rejected") | P6: =(L6+M6)/($K$3-O6) | Q6: =L6/$K$3 | R6: =COUNTIF(AL12:AL10000,"Pass") | S6: =COUNTIF(AL12:AL10000,"Fail") | T6: =$K$3-R6-S6-U6 | U6: =COUNTIF(AL12:AL10000,"Rejected") | V6: =(R6+S6)/($K$3-U6) | W6: =R6/$K$3 | X6: =COUNTIF(BE12:BE10000,"Pass") | Y6: =COUNTIF(BE12:BE10000,"Fail") | Z6: =$K$3-X6-Y6-AA6 | AA6: =COUNTIF(BE12:BE10000,"Rejected") | AB6: =(X6+Y6)/($K$3-AA6) | AC6: =X6/$K$3
G7: =Report!C8 | L7: =COUNTIF(V12:V10000,"Pass") | M7: =COUNTIF(V12:V10000,"Fail") | N7: =$K$3-L7-M7-O7 | O7: =COUNTIF(V12:V10000,"Rejected") | P7: =(L7+M7)/($K$3-O7) | Q7: =L7/$K$3 | R7: =COUNTIF(AO12:AO10000,"Pass") | S7: =COUNTIF(AO12:AO10000,"Fail") | T7: =$K$3-R7-S7-U7 | U7: =COUNTIF(AO12:AO10000,"Rejected") | V7: =(R7+S7)/($K$3-U7) | W7: =R7/$K$3 | X7: =COUNTIF(BH12:BH10000,"Pass") | Y7: =COUNTIF(BH12:BH10000,"Fail") | Z7: =$K$3-X7-Y7-AA7 | AA7: =COUNTIF(BH12:BH10000,"Rejected") | AB7: =(X7+Y7)/($K$3-AA7) | AC7: =X7/$K$3
G8: =Report!C9 | L8: =COUNTIF(Y12:Y10000,"Pass") | M8: =COUNTIF(Y12:Y10000,"Fail") | N8: =$K$3-L8-M8-O8 | O8: =COUNTIF(Y12:Y10000,"Rejected") | P8: =(L8+M8)/($K$3-O8) | Q8: =L8/$K$3 | R8: =COUNTIF(AR12:AR10000,"Pass") | S8: =COUNTIF(AR12:AR10000,"Fail") | T8: =$K$3-R8-S8-U8 | U8: =COUNTIF(AR12:AR10000,"Rejected") | V8: =(R8+S8)/($K$3-U8) | W8: =R8/$K$3 | X8: =COUNTIF(BK12:BK10000,"Pass") | Y8: =COUNTIF(BK12:BK10000,"Fail") | Z8: =$K$3-X8-Y8-AA8 | AA8: =COUNTIF(BK12:BK10000,"Rejected") | AB8: =(X8+Y8)/($K$3-AA8) | AC8: =X8/$K$3
A10: ID | B10: Category | C10: Name | D10: Precondition | E10: Performance steps(test steps) | F10: Test Data | G10: Expected result | H10: Priority | I10: Test result - Round 1 | AB10: Test result - Round 2 | AU10: Test result - Round 3 | BN10: Note
I11: BugID | J11: =Report!C4 | K11: Tester | L11: Date | M11: =Report!C5 | N11: Tester | O11: Date | P11: =G5 | Q11: Tester | R11: Date | S11: =G6 | T11: Tester | U11: Date | V11: =G7 | W11: Tester | X11: Date | Y11: =G8 | Z11: Date | AA11: Tester | AB11: BugID | AC11: =G3 | AD11: Tester | AE11: Date | AF11: =G4 | AG11: Tester | AH11: Date | AI11: =G5 | AJ11: Tester | AK11: Date | AL11: =G6 | AM11: Tester | AN11: Date | AO11: =G7 | AP11: Tester | AQ11: Date | AR11: =G8 | AS11: Date | AT11: Tester | AU11: BugID | AV11: =Report!C4 | AW11: Tester | AX11: Date | AY11: =Report!C5 | AZ11: Tester | BA11: Date | BB11: =Report!C6 | BC11: Tester | BD11: Date | BE11: =Report!C7 | BF11: Tester | BG11: Date | BH11: =Report!C8 | BI11: Tester | BJ11: Date | BK11: =Report!C9 | BL11: Date | BM11: Tester
